[qnode0023:939555] mca_base_component_repository_open: unable to open mca_mtl_psm: libpsm_infinipath.so.1: cannot open shared object file: No such file or directory (ignored)
[qnode0022:3800168] mca_base_component_repository_open: unable to open mca_mtl_psm: libpsm_infinipath.so.1: cannot open shared object file: No such file or directory (ignored)
[qnode0024:3231314] mca_base_component_repository_open: unable to open mca_mtl_psm: libpsm_infinipath.so.1: cannot open shared object file: No such file or directory (ignored)
[qnode0021:3627297] mca_base_component_repository_open: unable to open mca_mtl_psm: libpsm_infinipath.so.1: cannot open shared object file: No such file or directory (ignored)
Traceback (most recent call last):
  File "/gpfs/home/exy4679/duckdb_test/src/distributed_join_customer_orders.py", line 375, in <module>
    main()
  File "/gpfs/home/exy4679/duckdb_test/src/distributed_join_customer_orders.py", line 362, in main
    local_join_time, collection_time = collect_utils.collect_results_parquet_streaming(comm, rank, size, conn)
  File "/gpfs/home/exy4679/duckdb_test/src/utils/collect_utils.py", line 35, in collect_results_parquet_streaming
    print(f"Rank {rank}: Local join query completed in {query_time.seconds()}")
TypeError: 'int' object is not callable
Traceback (most recent call last):
Traceback (most recent call last):
  File "/gpfs/home/exy4679/duckdb_test/src/distributed_join_customer_orders.py", line 375, in <module>
  File "/gpfs/home/exy4679/duckdb_test/src/distributed_join_customer_orders.py", line 375, in <module>
        main()main()
  File "/gpfs/home/exy4679/duckdb_test/src/distributed_join_customer_orders.py", line 362, in main

  File "/gpfs/home/exy4679/duckdb_test/src/distributed_join_customer_orders.py", line 362, in main
    local_join_time, collection_time = collect_utils.collect_results_parquet_streaming(comm, rank, size, conn)
  File "/gpfs/home/exy4679/duckdb_test/src/utils/collect_utils.py", line 35, in collect_results_parquet_streaming
    print(f"Rank {rank}: Local join query completed in {query_time.seconds()}")
TypeError:     local_join_time, collection_time = collect_utils.collect_results_parquet_streaming(comm, rank, size, conn)
'int' object is not callable
  File "/gpfs/home/exy4679/duckdb_test/src/utils/collect_utils.py", line 35, in collect_results_parquet_streaming
    print(f"Rank {rank}: Local join query completed in {query_time.seconds()}")
TypeError: 'int' object is not callable
Traceback (most recent call last):
  File "/gpfs/home/exy4679/duckdb_test/src/distributed_join_customer_orders.py", line 375, in <module>
    main()
  File "/gpfs/home/exy4679/duckdb_test/src/distributed_join_customer_orders.py", line 362, in main
    local_join_time, collection_time = collect_utils.collect_results_parquet_streaming(comm, rank, size, conn)
  File "/gpfs/home/exy4679/duckdb_test/src/utils/collect_utils.py", line 35, in collect_results_parquet_streaming
    print(f"Rank {rank}: Local join query completed in {query_time.seconds()}")
TypeError: 'int' object is not callable
--------------------------------------------------------------------------
Primary job  terminated normally, but 1 process returned
a non-zero exit code. Per user-direction, the job has been aborted.
--------------------------------------------------------------------------
--------------------------------------------------------------------------
mpirun detected that one or more processes exited with non-zero status, thus causing
the job to be terminated. The first process to do so was:

  Process name: [[26365,1],1]
  Exit code:    1
--------------------------------------------------------------------------
